Workbook

Sheet Index
B2: Worksheets
B4: # | C4: Name | D4: Title
B5: 1 | C5: Index
B6: 2 | C6: Tabelle2 | D6: Information on data source
B7: 3 | C7: Table S4 | D7: Table S4
B8: 4 | C8: Table S5 weighted avg | D8: Table S5
B9: 5 | C9: pivot tables | D9: pivot tables
B10: 6 | C10: Table4.A FL | D10: country
B11: 7 | C11: Total HWP Domestic gains | D11: country

Sheet Tabelle2
A1: Information on data source
B4: Website: | C4: https://unfccc.int/ghg-inventories-annex-i-parties/2025
B5: Last updated: | C5: January 23, 2026
B6: Download: | C6: January 2, 2026
B7: Supplement data file to Böttcher et al.: Too many losses and too few gains: declining forest-sector Carbon Dioxide Removals in Europe's GHG accounts

Sheet Table S4
A1: Table S4
B3: Country | C3: 1990-2008 | D3: 2009-2017 | E3: 2018-2023 | G3: Country | H3: 2000 | I3: 2001 | J3: 2002 | K3: 2003 | L3: 2004 | M3: 2005 | N3: 2006 | O3: 2007 | P3: 2008 | Q3: 2009 | R3: 2010 | S3: 2011 | T3: 2012 | U3: 2013 | V3: 2014 | W3: 2015 | X3: 2016 | Y3: 2017 | Z3: 2018 | AA3: 2019 | AB3: 2020 | AC3: 2021 | AD3: 2022 | AE3: 2023
B4: Austria | C4: =AVERAGE(C88:U88) -> -0.40198961 | D4: =AVERAGE(V88:AD88) -> -0.33294289 | E4: =AVERAGE(AE88:AJ88) -> -0.27304512 | G4: Austria | H4: -0.42848631 | I4: -0.46384929 | J4: -0.42628872 | K4: -0.40179481 | L4: -0.39299493 | M4: -0.39901451 | N4: -0.36064146 | O4: -0.36834041 | P4: -0.35888133 | Q4: -0.33179841 | R4: -0.35701842 | S4: -0.34826225 | T4: -0.34106017 | U4: -0.3217864 | V4: -0.33210686 | W4: -0.3148671 | X4: -0.32369579 | Y4: -0.32589061 | Z4: -0.30908489 | AA4: -0.26794322 | AB4: -0.25673681 | AC4: -0.28522407 | AD4: -0.27536465 | AE4: -0.2439171
B5: Croatia | C5: =AVERAGE(C94:U94) -> -0.060109333 | D5: =AVERAGE(V94:AD94) -> -0.051968725 | E5: =AVERAGE(AE94:AJ94) -> -0.056771641 | G5: Croatia | H5: -0.15317281 | I5: -0.19803329 | J5: -0.21290779 | K5: -0.19441589 | L5: -0.19217722 | M5: -0.22568877 | N5: -0.22400016 | O5: -0.21348894 | P5: -0.21786981 | Q5: -0.21126833 | R5: -0.21891333 | S5: -0.19775535 | T5: -0.20144326 | U5: -0.20926011 | V5: -0.20461703 | W5: -0.21469732 | X5: -0.21193512 | Y5: -0.23251982 | Z5: -0.20208515 | AA5: -0.2062631 | AB5: -0.20137596 | AC5: -0.20147825 | AD5: -0.17035184 | AE5: -0.17343351
B6: Czechia | C6: =AVERAGE(C89:U89) -> -0.19303597 | D6: =AVERAGE(V89:AD89) -> -0.21137885 | E6: =AVERAGE(AE89:AJ89) -> -0.19249797 | G6: Czechia | H6: -0.25584333 | I6: -0.25699829 | J6: -0.25281148 | K6: -0.26727035 | L6: -0.26582883 | M6: -0.26474899 | N6: -0.27931529 | O6: -0.29432338 | P6: -0.29540942 | Q6: -0.25713937 | R6: -0.26495435 | S6: -0.25789098 | T6: -0.24544048 | U6: -0.20964492 | V6: -0.20327374 | W6: -0.21393886 | X6: -0.21383055 | Y6: -0.20737194 | Z6: -0.17090153 | AA6: -0.14749703 | AB6: -0.16041865 | AC6: -0.18004207 | AD6: -0.20249354 | AE6: -0.24071922
B7: Estonia | C7: =AVERAGE(C90:U90) -> -0.26504294 | D7: =AVERAGE(V90:AD90) -> -0.23038724 | E7: =AVERAGE(AE90:AJ90) -> -0.18367867 | G7: Estonia | H7: -0.21040994 | I7: -0.1874057 | J7: -0.155837 | K7: -0.18598812 | L7: -0.17089121 | M7: -0.18765424 | N7: -0.23413498 | O7: -0.25143831 | P7: -0.27715407 | Q7: -0.28242188 | R7: -0.2657019 | S7: -0.18839344 | T7: -0.15959903 | U7: -0.15318425 | V7: -0.16466053 | W7: -0.1781116 | X7: -0.18274586 | Y7: -0.18222607 | Z7: -0.16724604 | AA7: -0.16279948 | AB7: -0.1913531 | AC7: -0.19885431 | AD7: -0.1879407 | AE7: -0.14891736
B8: Finland | C8: =AVERAGE(C91:U91) -> -0.29265023 | D8: =AVERAGE(V91:AD91) -> -0.19522717 | E8: =AVERAGE(AE91:AJ91) -> -0.17618516 | G8: Finland | H8: -0.28213771 | I8: -0.26602531 | J8: -0.2662766 | K8: -0.2698364 | L8: -0.27546345 | M8: -0.24605729 | N8: -0.28362249 | O8: -0.26790894 | P8: -0.24678586 | Q8: -0.24287606 | R8: -0.23939159 | S8: -0.23768505 | T8: -0.23537228 | U8: -0.22297922 | V8: -0.23015772 | W8: -0.22171327 | X8: -0.225904 | Y8: -0.23049562 | Z8: -0.22033215 | AA8: -0.227323 | AB8: -0.21837898 | AC8: -0.2183381 | AD8: -0.21916066 | AE8: -0.21072234
B9: France | C9: =AVERAGE(C92:U92) -> -0.27375697 | D9: =AVERAGE(V92:AD92) -> -0.23184165 | E9: =AVERAGE(AE92:AJ92) -> -0.21904254 | G9: France | H9: -0.16243879 | I9: -0.17814787 | J9: -0.18278269 | K9: -0.1885744 | L9: -0.19473503 | M9: -0.20258076 | N9: -0.20591127 | O9: -0.21129796 | P9: -0.20228418 | Q9: -0.13415341 | R9: -0.180872 | S9: -0.18982023 | T9: -0.1903684 | U9: -0.18590266 | V9: -0.17330506 | W9: -0.16216436 | X9: -0.14810337 | Y9: -0.13704203 | Z9: -0.12783914 | AA9: -0.11899991 | AB9: -0.10641009 | AC9: -0.12180073 | AD9: -0.11978216 | AE9: -0.11527636
B10: Italy | C10: =AVERAGE(C95:U95) -> -0.11589879 | D10: =AVERAGE(V95:AD95) -> -0.12207347 | E10: =AVERAGE(AE95:AJ95) -> -0.13616408 | G10: Italy | H10: -0.056774066 | I10: -0.057480432 | J10: -0.063348792 | K10: -0.057259991 | L10: -0.065075361 | M10: -0.064612811 | N10: -0.068919833 | O10: -0.052937164 | P10: -0.066253904 | Q10: -0.060353542 | R10: -0.059726078 | S10: -0.049857346 | T10: -0.043451878 | U10: -0.05057141 | V10: -0.052703806 | W10: -0.055168152 | X10: -0.055436515 | Y10: -0.0404498 | Z10: -0.048899856 | AA10: -0.076889035 | AB10: -0.055565956 | AC10: -0.049209957 | AD10: -0.049887639 | AE10: -0.060177404
B11: Latvia | C11: =AVERAGE(C96:U96) -> -0.18985263 | D11: =AVERAGE(V96:AD96) -> -0.18434049 | E11: =AVERAGE(AE96:AJ96) -> -0.18583309 | G11: Latvia | H11: -0.14698418 | I11: -0.14931929 | J11: -0.14485922 | K11: -0.14199615 | L11: -0.14573416 | M11: -0.14500725 | N11: -0.16497768 | O11: -0.12306187 | P11: -0.12006305 | Q11: -0.10102362 | R11: -0.10914481 | S11: -0.12297282 | T11: -0.1263825 | U11: -0.12634978 | V11: -0.11784678 | W11: -0.1228724 | X11: -0.12925969 | Y11: -0.14280887 | Z11: -0.1364244 | AA11: -0.14323737 | AB11: -0.13294326 | AC11: -0.14922966 | AD11: -0.12308318 | AE11: -0.1320666
B12: Portugal | C12: =AVERAGE(C97:U97) -> -0.19949737 | D12: =AVERAGE(V97:AD97) -> -0.36273743 | E12: =AVERAGE(AE97:AJ97) -> -0.33267095 | G12: Portugal | H12: -0.17268361 | I12: -0.18703201 | J12: -0.19641352 | K12: -0.1997158 | L12: -0.18687454 | M12: -0.19166012 | N12: -0.18020794 | O12: -0.17364578 | P12: -0.19222071 | Q12: -0.20557202 | R12: -0.18794903 | S12: -0.1784279 | T12: -0.19055776 | U12: -0.16820293 | V12: -0.17457843 | W12: -0.18822754 | X12: -0.18695379 | Y12: -0.17859499 | Z12: -0.19011143 | AA12: -0.18859635 | AB12: -0.18476685 | AC12: -0.18808134 | AD12: -0.18307853 | AE12: -0.18036405
B13: Romania | C13: =AVERAGE(C98:U98) -> -0.20192784 | D13: =AVERAGE(V98:AD98) -> -0.19326468 | E13: =AVERAGE(AE98:AJ98) -> -0.18076941 | G13: Romania | H13: -0.20508698 | I13: -0.20819162 | J13: -0.21648078 | K13: -0.25178045 | L13: -0.26554407 | M13: -0.26020037 | N13: -0.24087206 | O13: -0.26687524 | P13: -0.27484777 | Q13: -0.26145745 | R13: -0.31125793 | S13: -0.30317951 | T13: -0.37175377 | U13: -0.39334429 | V13: -0.40347341 | W13: -0.40083703 | X13: -0.42080045 | Y13: -0.39853298 | Z13: -0.35108077 | AA13: -0.37012941 | AB13: -0.35690034 | AC13: -0.34223259 | AD13: -0.28435974 | AE13: -0.29132285
B14: Slovakia | C14: =AVERAGE(C99:U99) -> -1.0880995 | D14: =AVERAGE(V99:AD99) -> -0.55004863 | E14: =AVERAGE(AE99:AJ99) -> -2.6785216 | G14: Slovakia | H14: -0.2388584 | I14: -0.18250128 | J14: -0.21342212 | K14: -0.22085963 | L14: -0.23313141 | M14: -0.22508238 | N14: -0.26948108 | O14: -0.27847876 | P14: -0.25167844 | Q14: -0.22906633 | R14: -0.20545563 | S14: -0.19329271 | T14: -0.17804958 | U14: -0.18011988 | V14: -0.16948863 | W14: -0.18857778 | X14: -0.19603568 | Y14: -0.19929589 | Z14: -0.18015432 | AA14: -0.17634272 | AB14: -0.18065141 | AC14: -0.18740075 | AD14: -0.16829949 | AE14: -0.1917678
B15: Slovenia | C15: =AVERAGE(C100:U100) -> -0.14293591 | D15: =AVERAGE(V100:AD100) -> -0.12270673 | E15: =AVERAGE(AE100:AJ100) -> -0.11504124 | G15: Slovenia | H15: -0.73674165 | I15: -0.68218644 | J15: -0.65771706 | K15: -0.69277557 | L15: -0.73213178 | M15: -0.76097626 | N15: -0.79670231 | O15: -0.87666234 | P15: -0.80506857 | Q15: -0.76633772 | R15: -0.72238946 | S15: -0.72829089 | T15: -0.77973933 | U15: -0.80833252 | V15: -0.27582519 | W15: -0.29009548 | X15: -0.28883709 | Y15: -0.29058999 | Z15: -0.31262112 | AA15: -1.9453522 | AB15: -2.1099514 | AC15: -2.8738317 | AD15: -4.4709418 | AE15: -4.3584314
B16: UK | C16: =AVERAGE(C93:U93) -> -0.17255954 | D16: =AVERAGE(V93:AD93) -> -0.16685906 | E16: =AVERAGE(AE93:AJ93) -> -0.1183514 | G16: UK | H16: -0.15259054 | I16: -0.14923156 | J16: -0.14782481 | K16: -0.15054542 | L16: -0.14595938 | M16: -0.14258456 | N16: -0.13427819 | O16: -0.1332626 | P16: -0.12555852 | Q16: -0.12095163 | R16: -0.12235222 | S16: -0.12449612 | T16: -0.13020303 | U16: -0.1240825 | V16: -0.1214911 | W16: -0.12283159 | X16: -0.12086217 | Y16: -0.11709026 | Z16: -0.11529379 | AA16: -0.11279238 | AB16: -0.11198375 | AC16: -0.11824637 | AD16: -0.11592954 | AE16: -0.11600158
C21: wrongunit <- c("TUR","BEL","ESP","FRA","GRC","PRT","NOR","SVK","SWE”)
B22: HWP in use from domestic harvest (t C/ha)
B23: Country | C23: 1990 | D23: 1991 | E23: 1992 | F23: 1993 | G23: 1994 | H23: 1995 | I23: 1996 | J23: 1997 | K23: 1998 | L23: 1999 | M23: 2000 | N23: 2001 | O23: 2002 | P23: 2003 | Q23: 2004 | R23: 2005 | S23: 2006 | T23: 2007 | U23: 2008 | V23: 2009 | W23: 2010 | X23: 2011 | Y23: 2012 | Z23: 2013 | AA23: 2014 | AB23: 2015 | AC23: 2016 | AD23: 2017 | AE23: 2018 | AF23: 2019 | AG23: 2020 | AH23: 2021 | AI23: 2022 | AJ23: 2023
B24: AUT | C24: ='pivot tables'!D40/'pivot tables'!D7 -> 0.62546485 | D24: ='pivot tables'!E40/'pivot tables'!E7 -> 0.56221325 | E24: ='pivot tables'!F40/'pivot tables'!F7 -> 0.54870555 | F24: ='pivot tables'!G40/'pivot tables'!G7 -> 0.54027308 | G24: ='pivot tables'!H40/'pivot tables'!H7 -> 0.6121141 | H24: ='pivot tables'!I40/'pivot tables'!I7 -> 0.61904805 | I24: ='pivot tables'!J40/'pivot tables'!J7 -> 0.65489671 | J24: ='pivot tables'!K40/'pivot tables'!K7 -> 0.64302804 | ... AJ24: ='pivot tables'!AK40/'pivot tables'!AK7 -> 0.60614889
B25: BEL | C25: ='pivot tables'!D41/'pivot tables'!D8/1000 -> 0.99867325 | D25: ='pivot tables'!E41/'pivot tables'!E8/1000 -> 0.85762474 | E25: ='pivot tables'!F41/'pivot tables'!F8/1000 -> 0.80989973 | F25: ='pivot tables'!G41/'pivot tables'!G8/1000 -> 0.8325455 | G25: ='pivot tables'!H41/'pivot tables'!H8/1000 -> 0.75346373 | H25: ='pivot tables'!I41/'pivot tables'!I8/1000 -> 0.85897321 | I25: ='pivot tables'!J41/'pivot tables'!J8/1000 -> 0.95518284 | J25: ='pivot tables'!K41/'pivot tables'!K8/1000 -> 0.79228689 | ... AJ25: ='pivot tables'!AK41/'pivot tables'!AK8/1000 -> 0.43340094
B26: BGR | C26: ='pivot tables'!D42/'pivot tables'!D9 -> 0.11862676 | D26: ='pivot tables'!E42/'pivot tables'!E9 -> 0.10936029 | E26: ='pivot tables'!F42/'pivot tables'!F9 -> 0.054903366 | F26: ='pivot tables'!G42/'pivot tables'!G9 -> 0.047017161 | G26: ='pivot tables'!H42/'pivot tables'!H9 -> 0.048233211 | H26: ='pivot tables'!I42/'pivot tables'!I9 -> 0.050124449 | I26: ='pivot tables'!J42/'pivot tables'!J9 -> 0.057500469 | J26: ='pivot tables'!K42/'pivot tables'!K9 -> 0.062258251 | ... AJ26: ='pivot tables'!AK42/'pivot tables'!AK9 -> 0.2318171
B27: CHE | C27: ='pivot tables'!D43/'pivot tables'!D10 -> 0 | D27: ='pivot tables'!E43/'pivot tables'!E10 -> 0 | E27: ='pivot tables'!F43/'pivot tables'!F10 -> 0 | F27: ='pivot tables'!G43/'pivot tables'!G10 -> 0 | G27: ='pivot tables'!H43/'pivot tables'!H10 -> 0 | H27: ='pivot tables'!I43/'pivot tables'!I10 -> 0 | I27: ='pivot tables'!J43/'pivot tables'!J10 -> 0 | J27: ='pivot tables'!K43/'pivot tables'!K10 -> 0 | ... AJ27: ='pivot tables'!AK43/'pivot tables'!AK10 -> 0
B28: CZE | C28: ='pivot tables'!D44/'pivot tables'!D11 -> 0.56004076 | D28: ='pivot tables'!E44/'pivot tables'!E11 -> 0.4204952 | E28: ='pivot tables'!F44/'pivot tables'!F11 -> 0.29812009 | F28: ='pivot tables'!G44/'pivot tables'!G11 -> 0.39753701 | G28: ='pivot tables'!H44/'pivot tables'!H11 -> 0.40810898 | H28: ='pivot tables'!I44/'pivot tables'!I11 -> 0.44862447 | I28: ='pivot tables'!J44/'pivot tables'!J11 -> 0.44128513 | J28: ='pivot tables'!K44/'pivot tables'!K11 -> 0.44803292 | ... AJ28: ='pivot tables'!AK44/'pivot tables'!AK11 -> 0.56162888
B29: DEU | C29: ='pivot tables'!D45/'pivot tables'!D12 -> 0.66656768 | D29: ='pivot tables'!E45/'pivot tables'!E12 -> 0.6233069 | E29: ='pivot tables'!F45/'pivot tables'!F12 -> 0.64122794 | F29: ='pivot tables'!G45/'pivot tables'!G12 -> 0.62329298 | G29: ='pivot tables'!H45/'pivot tables'!H12 -> 0.7161264 | H29: ='pivot tables'!I45/'pivot tables'!I12 -> 0.72715542 | I29: ='pivot tables'!J45/'pivot tables'!J12 -> 0.75360312 | J29: ='pivot tables'!K45/'pivot tables'!K12 -> 0.7714152 | ... AJ29: ='pivot tables'!AK45/'pivot tables'!AK12 -> 1.136886
B30: DNK | C30: ='pivot tables'!D46/'pivot tables'!D13 -> 0.26539215 | D30: ='pivot tables'!E46/'pivot tables'!E13 -> 0.19882341 | E30: ='pivot tables'!F46/'pivot tables'!F13 -> 0.291295 | F30: ='pivot tables'!G46/'pivot tables'!G13 -> 0.41921691 | G30: ='pivot tables'!H46/'pivot tables'!H13 -> 0.38562914 | H30: ='pivot tables'!I46/'pivot tables'!I13 -> 0.38104028 | I30: ='pivot tables'!J46/'pivot tables'!J13 -> 0.399963 | J30: ='pivot tables'!K46/'pivot tables'!K13 -> 0.35316751 | ... AJ30: ='pivot tables'!AK46/'pivot tables'!AK13 -> 0.27097196
B31: ESP | C31: ='pivot tables'!D47/'pivot tables'!D14/1000 -> 0.13912132 | D31: ='pivot tables'!E47/'pivot tables'!E14/1000 -> 0.14087486 | E31: ='pivot tables'!F47/'pivot tables'!F14/1000 -> 0.11819101 | F31: ='pivot tables'!G47/'pivot tables'!G14/1000 -> 0.12803305 | G31: ='pivot tables'!H47/'pivot tables'!H14/1000 -> 0.13081747 | H31: ='pivot tables'!I47/'pivot tables'!I14/1000 -> 0.13700703 | I31: ='pivot tables'!J47/'pivot tables'!J14/1000 -> 0.13479488 | J31: ='pivot tables'!K47/'pivot tables'!K14/1000 -> 0.13013888 | ... AJ31: ='pivot tables'!AK47/'pivot tables'!AK14/1000 -> 0.15345212
B32: EST | C32: ='pivot tables'!D48/'pivot tables'!D15 -> 0.077745224 | D32: ='pivot tables'!E48/'pivot tables'!E15 -> 0.062505164 | E32: ='pivot tables'!F48/'pivot tables'!F15 -> 0.047280095 | F32: ='pivot tables'!G48/'pivot tables'!G15 -> 0.052449507 | G32: ='pivot tables'!H48/'pivot tables'!H15 -> 0.056911468 | H32: ='pivot tables'!I48/'pivot tables'!I15 -> 0.062201416 | I32: ='pivot tables'!J48/'pivot tables'!J15 -> 0.076015695 | J32: ='pivot tables'!K48/'pivot tables'!K15 -> 0.10637121 | ... AJ32: ='pivot tables'!AK48/'pivot tables'!AK15 -> 0.18956624
B33: FIN | C33: ='pivot tables'!D49/'pivot tables'!D16 -> 0.24216383 | D33: ='pivot tables'!E49/'pivot tables'!E16 -> 0.2208558 | E33: ='pivot tables'!F49/'pivot tables'!F16 -> 0.22582993 | F33: ='pivot tables'!G49/'pivot tables'!G16 -> 0.2570571 | G33: ='pivot tables'!H49/'pivot tables'!H16 -> 0.2818584 | H33: ='pivot tables'!I49/'pivot tables'!I16 -> 0.2809525 | I33: ='pivot tables'!J49/'pivot tables'!J16 -> 0.27507579 | J33: ='pivot tables'!K49/'pivot tables'!K16 -> 0.31414667 | ... AJ33: ='pivot tables'!AK49/'pivot tables'!AK16 -> 0.29118548
B34: FRA | C34: ='pivot tables'!D50/'pivot tables'!D17/1000 -> 0.1907879 | D34: ='pivot tables'!E50/'pivot tables'!E17/1000 -> 0.18879127 | E34: ='pivot tables'!F50/'pivot tables'!F17/1000 -> 0.16678457 | F34: ='pivot tables'!G50/'pivot tables'!G17/1000 -> 0.15267231 | G34: ='pivot tables'!H50/'pivot tables'!H17/1000 -> 0.163775 | H34: ='pivot tables'!I50/'pivot tables'!I17/1000 -> 0.16919137 | I34: ='pivot tables'!J50/'pivot tables'!J17/1000 -> 0.1630921 | J34: ='pivot tables'!K50/'pivot tables'!K17/1000 -> 0.17073714 | ... AJ34: ='pivot tables'!AK50/'pivot tables'!AK17/1000 -> 0.14392134
B35: GBR | C35: ='pivot tables'!D51/'pivot tables'!D18 -> 0.37780744 | D35: ='pivot tables'!E51/'pivot tables'!E18 -> 0.36844374 | E35: ='pivot tables'!F51/'pivot tables'!F18 -> 0.37513542 | F35: ='pivot tables'!G51/'pivot tables'!G18 -> 0.3806573 | G35: ='pivot tables'!H51/'pivot tables'!H18 -> 0.40407495 | H35: ='pivot tables'!I51/'pivot tables'!I18 -> 0.41333268 | I35: ='pivot tables'!J51/'pivot tables'!J18 -> 0.41082592 | J35: ='pivot tables'!K51/'pivot tables'!K18 -> 0.42702486 | ... AJ35: ='pivot tables'!AK51/'pivot tables'!AK18 -> 0.44758733
B36: GRC | C36: ='pivot tables'!D52/'pivot tables'!D19/1000 -> 0.052242278 | D36: ='pivot tables'!E52/'pivot tables'!E19/1000 -> 0.052765044 | E36: ='pivot tables'!F52/'pivot tables'!F19/1000 -> 0.0451243 | F36: ='pivot tables'!G52/'pivot tables'!G19/1000 -> 0.065372925 | G36: ='pivot tables'!H52/'pivot tables'!H19/1000 -> 0.067264901 | H36: ='pivot tables'!I52/'pivot tables'!I19/1000 -> 0.06441527 | I36: ='pivot tables'!J52/'pivot tables'!J19/1000 -> 0.067676947 | J36: ='pivot tables'!K52/'pivot tables'!K19/1000 -> 0.02064105 | ... AJ36: ='pivot tables'!AK52/'pivot tables'!AK19/1000 -> 0.029202793
B37: HRV | C37: ='pivot tables'!D53/'pivot tables'!D20 -> 0.17945077 | D37: ='pivot tables'!E53/'pivot tables'!E20 -> 0.11638108 | E37: ='pivot tables'!F53/'pivot tables'!F20 -> 0.095535969 | F37: ='pivot tables'!G53/'pivot tables'!G20 -> 0.10526337 | G37: ='pivot tables'!H53/'pivot tables'!H20 -> 0.11342211 | H37: ='pivot tables'!I53/'pivot tables'!I20 -> 0.11517835 | I37: ='pivot tables'!J53/'pivot tables'!J20 -> 0.11128619 | J37: ='pivot tables'!K53/'pivot tables'!K20 -> 0.093673176 | ... AJ37: ='pivot tables'!AK53/'pivot tables'!AK20 -> 0.18235056
B38: IRL | C38: ='pivot tables'!D54/'pivot tables'!D21 -> 0.31182273 | D38: ='pivot tables'!E54/'pivot tables'!E21 -> 0.30296351 | E38: ='pivot tables'!F54/'pivot tables'!F21 -> 0.37843405 | F38: ='pivot tables'!G54/'pivot tables'!G21 -> 0.38665006 | G38: ='pivot tables'!H54/'pivot tables'!H21 -> 0.40893667 | H38: ='pivot tables'!I54/'pivot tables'!I21 -> 0.4153269 | I38: ='pivot tables'!J54/'pivot tables'!J21 -> 0.45889933 | J38: ='pivot tables'!K54/'pivot tables'!K21 -> 0.46069299 | ... AJ38: ='pivot tables'!AK54/'pivot tables'!AK21 -> 0.58406754
B39: ITA | C39: ='pivot tables'!D55/'pivot tables'!D22 -> 0.10599684 | D39: ='pivot tables'!E55/'pivot tables'!E22 -> 0.092892883 | E39: ='pivot tables'!F55/'pivot tables'!F22 -> 0.079044531 | F39: ='pivot tables'!G55/'pivot tables'!G22 -> 0.088749458 | G39: ='pivot tables'!H55/'pivot tables'!H22 -> 0.076982105 | H39: ='pivot tables'!I55/'pivot tables'!I22 -> 0.10512944 | I39: ='pivot tables'!J55/'pivot tables'!J22 -> 0.1081926 | J39: ='pivot tables'!K55/'pivot tables'!K22 -> 0.1046337 | ... AJ39: ='pivot tables'!AK55/'pivot tables'!AK22 -> 0.074283239
B40: LTU | C40: ='pivot tables'!D56/'pivot tables'!D23 -> 0.14123545 | D40: ='pivot tables'!E56/'pivot tables'!E23 -> 0.14347627 | E40: ='pivot tables'!F56/'pivot tables'!F23 -> 0.061679344 | F40: ='pivot tables'!G56/'pivot tables'!G23 -> 0.11573529 | G40: ='pivot tables'!H56/'pivot tables'!H23 -> 0.17785606 | H40: ='pivot tables'!I56/'pivot tables'!I23 -> 0.20198753 | I40: ='pivot tables'!J56/'pivot tables'!J23 -> 0.2452114 | J40: ='pivot tables'!K56/'pivot tables'!K23 -> 0.21565568 | ... AJ40: ='pivot tables'!AK56/'pivot tables'!AK23 -> 0.39348549
B41: LVA | C41: ='pivot tables'!D57/'pivot tables'!D24 -> 0.099352586 | D41: ='pivot tables'!E57/'pivot tables'!E24 -> 0.099308922 | E41: ='pivot tables'!F57/'pivot tables'!F24 -> 0.081138766 | F41: ='pivot tables'!G57/'pivot tables'!G24 -> 0.051553116 | G41: ='pivot tables'!H57/'pivot tables'!H24 -> 0.09311633 | H41: ='pivot tables'!I57/'pivot tables'!I24 -> 0.12559863 | I41: ='pivot tables'!J57/'pivot tables'!J24 -> 0.14406771 | J41: ='pivot tables'!K57/'pivot tables'!K24 -> 0.22064805 | ... AJ41: ='pivot tables'!AK57/'pivot tables'!AK24 -> 0.37006372
B42: NOR | C42: ='pivot tables'!D58/'pivot tables'!D25 -> 0.11728106 | D42: ='pivot tables'!E58/'pivot tables'!E25 -> 0.11148973 | E42: ='pivot tables'!F58/'pivot tables'!F25 -> 0.10988313 | F42: ='pivot tables'!G58/'pivot tables'!G25 -> 0.11644348 | G42: ='pivot tables'!H58/'pivot tables'!H25 -> 0.12587445 | H42: ='pivot tables'!I58/'pivot tables'!I25 -> 0.12541039 | I42: ='pivot tables'!J58/'pivot tables'!J25 -> 0.12380879 | J42: ='pivot tables'!K58/'pivot tables'!K25 -> 0.12648372 | ... AJ42: ='pivot tables'!AK58/'pivot tables'!AK25 -> 0.087884691
B43: POL | C43: ='pivot tables'!D59/'pivot tables'!D26 -> 0.059674942 | D43: ='pivot tables'!E59/'pivot tables'!E26 -> 0.054915322 | E43: ='pivot tables'!F59/'pivot tables'!F26 -> 0.065676629 | F43: ='pivot tables'!G59/'pivot tables'!G26 -> 0.074892466 | G43: ='pivot tables'!H59/'pivot tables'!H26 -> 0.087222277 | H43: ='pivot tables'!I59/'pivot tables'!I26 -> 0.078647758 | I43: ='pivot tables'!J59/'pivot tables'!J26 -> 0.076993115 | J43: ='pivot tables'!K59/'pivot tables'!K26 -> 0.088076443 | ... AJ43: ='pivot tables'!AK59/'pivot tables'!AK26 -> 0.25722763
B44: PRT | C44: ='pivot tables'!D60/'pivot tables'!D27/1000 -> 0.29694997 | D44: ='pivot tables'!E60/'pivot tables'!E27/1000 -> 0.29493008 | E44: ='pivot tables'!F60/'pivot tables'!F27/1000 -> 0.27492016 | F44: ='pivot tables'!G60/'pivot tables'!G27/1000 -> 0.26714843 | G44: ='pivot tables'!H60/'pivot tables'!H27/1000 -> 0.26556535 | H44: ='pivot tables'!I60/'pivot tables'!I27/1000 -> 0.2568017 | I44: ='pivot tables'!J60/'pivot tables'!J27/1000 -> 0.26867156 | J44: ='pivot tables'!K60/'pivot tables'!K27/1000 -> 0.25352546 | ... AJ44: ='pivot tables'!AK60/'pivot tables'!AK27/1000 -> 0.2906882
B45: ROU | C45: ='pivot tables'!D61/'pivot tables'!D28 -> 0.17285857 | D45: ='pivot tables'!E61/'pivot tables'!E28 -> 0.1315059 | E45: ='pivot tables'!F61/'pivot tables'!F28 -> 0.14233553 | F45: ='pivot tables'!G61/'pivot tables'!G28 -> 0.1437966 | G45: ='pivot tables'!H61/'pivot tables'!H28 -> 0.094944696 | H45: ='pivot tables'!I61/'pivot tables'!I28 -> 0.10192219 | I45: ='pivot tables'!J61/'pivot tables'!J28 -> 0.096873794 | J45: ='pivot tables'!K61/'pivot tables'!K28 -> 0.10081971 | ... AJ45: ='pivot tables'!AK61/'pivot tables'!AK28 -> 0.25712437
...

Sheet Table S5 weighted avg
A1: Table S5
B3: Country | C3: 1990 | D3: 1991 | E3: 1992 | F3: 1993 | G3: 1994 | H3: 1995 | I3: 1996 | J3: 1997 | K3: 1998 | L3: 1999 | M3: 2000 | N3: 2001 | O3: 2002 | P3: 2003 | Q3: 2004 | R3: 2005 | S3: 2006 | T3: 2007 | U3: 2008 | V3: 2009 | W3: 2010 | X3: 2011 | Y3: 2012 | Z3: 2013 | AA3: 2014 | AB3: 2015 | AC3: 2016 | AD3: 2017 | AE3: 2018 | AF3: 2019 | AG3: 2020 | AH3: 2021 | AI3: 2022 | AJ3: 2023
B4: Sum HWP gains | C4: =SUM(C21,C25,C29,C30,C31,C32,C34,C36,C38,C41,C42,C43,C44) -> 19767.785 | D4: =SUM(D21,D25,D29,D30,D31,D32,D34,D36,D38,D41,D42,D43,D44) -> 17926.377 | E4: =SUM(E21,E25,E29,E30,E31,E32,E34,E36,E38,E41,E42,E43,E44) -> 16828.552 | F4: =SUM(F21,F25,F29,F30,F31,F32,F34,F36,F38,F41,F42,F43,F44) -> 17512.291 | G4: =SUM(G21,G25,G29,G30,G31,G32,G34,G36,G38,G41,G42,G43,G44) -> 18530.466 | H4: =SUM(H21,H25,H29,H30,H31,H32,H34,H36,H38,H41,H42,H43,H44) -> 19191.715 | I4: =SUM(I21,I25,I29,I30,I31,I32,I34,I36,I38,I41,I42,I43,I44) -> 19243.192 | J4: =SUM(J21,J25,J29,J30,J31,J32,J34,J36,J38,J41,J42,J43,J44) -> 20607.898 | ... AJ4: =SUM(AJ21,AJ25,AJ29,AJ30,AJ31,AJ32,AJ34,AJ36,AJ38,AJ41,AJ42,AJ43,AJ44) -> 22558.27
B5: Sum Biomass losses | C5: =SUM(C54,C58,C62,C63,C64,C65,C67,C69,C71,C74,C75,C76,C77) -> -99736.004 | D5: =SUM(D54,D58,D62,D63,D64,D65,D67,D69,D71,D74,D75,D76,D77) -> -90585.335 | E5: =SUM(E54,E58,E62,E63,E64,E65,E67,E69,E71,E74,E75,E76,E77) -> -93220.666 | F5: =SUM(F54,F58,F62,F63,F64,F65,F67,F69,F71,F74,F75,F76,F77) -> -96678.861 | G5: =SUM(G54,G58,G62,G63,G64,G65,G67,G69,G71,G74,G75,G76,G77) -> -99856.043 | H5: =SUM(H54,H58,H62,H63,H64,H65,H67,H69,H71,H74,H75,H76,H77) -> -100422.39 | I5: =SUM(I54,I58,I62,I63,I64,I65,I67,I69,I71,I74,I75,I76,I77) -> -99128.913 | J5: =SUM(J54,J58,J62,J63,J64,J65,J67,J69,J71,J74,J75,J76,J77) -> -106434.47 | ... AJ5: =SUM(AJ54,AJ58,AJ62,AJ63,AJ64,AJ65,AJ67,AJ69,AJ71,AJ74,AJ75,AJ76,AJ77) -> -137690.63
B6: weighted avg | C6: =C4/C5 -> -0.1982011 | D6: =D4/D5 -> -0.19789491 | E6: =E4/E5 -> -0.18052384 | F6: =F4/F5 -> -0.18113878 | G6: =G4/G5 -> -0.1855718 | H6: =H4/H5 -> -0.19110992 | I6: =I4/I5 -> -0.1941229 | J6: =J4/J5 -> -0.19362053 | ... AJ6: =AJ4/AJ5 -> -0.16383301
B10: Country | C10: 1990-2008 | D10: 2009-2017 | E10: 2018-2023
B11: weighted avg | C11: =AVERAGE(C6:U6) -> -0.19804808 | D11: =AVERAGE(V6:AD6) -> -0.1884332 | E11: =AVERAGE(AE6:AJ6) -> -0.16792788
C18: wrongunit <- c("TUR","BEL","ESP","FRA","GRC","PRT","NOR","SVK","SWE”)
B19: HWP in use from domestic harvest (kt C)
B20: Country | C20: 1990 | D20: 1991 | E20: 1992 | F20: 1993 | G20: 1994 | H20: 1995 | I20: 1996 | J20: 1997 | K20: 1998 | L20: 1999 | M20: 2000 | N20: 2001 | O20: 2002 | P20: 2003 | Q20: 2004 | R20: 2005 | S20: 2006 | T20: 2007 | U20: 2008 | V20: 2009 | W20: 2010 | X20: 2011 | Y20: 2012 | Z20: 2013 | AA20: 2014 | AB20: 2015 | AC20: 2016 | AD20: 2017 | AE20: 2018 | AF20: 2019 | AG20: 2020 | AH20: 2021 | AI20: 2022 | AJ20: 2023
B21: AUT | C21: ='pivot tables'!D40 -> 2434.6331 | D21: ='pivot tables'!E40 -> 2192.7339 | E21: ='pivot tables'!F40 -> 2144.2568 | F21: ='pivot tables'!G40 -> 2115.4447 | G21: ='pivot tables'!H40 -> 2401.4302 | H21: ='pivot tables'!I40 -> 2431.8994 | I21: ='pivot tables'!J40 -> 2576.1843 | J21: ='pivot tables'!K40 -> 2532.8888 | ... AJ21: ='pivot tables'!AK40 -> 2439.2184
B22: BEL | C22: ='pivot tables'!D41/1000 -> 707.66053 | D22: ='pivot tables'!E41/1000 -> 607.99959 | E22: ='pivot tables'!F41/1000 -> 574.4359 | F22: ='pivot tables'!G41/1000 -> 590.77557 | G22: ='pivot tables'!H41/1000 -> 534.9104 | H22: ='pivot tables'!I41/1000 -> 610.10187 | I22: ='pivot tables'!J41/1000 -> 678.75525 | J22: ='pivot tables'!K41/1000 -> 563.27097 | ... AJ22: ='pivot tables'!AK41/1000 -> 311.7967
B23: BGR | C23: ='pivot tables'!D42 -> 451.87986 | D23: ='pivot tables'!E42 -> 417.03694 | E23: ='pivot tables'!F42 -> 209.59836 | F23: ='pivot tables'!G42 -> 179.68791 | G23: ='pivot tables'!H42 -> 184.53622 | H23: ='pivot tables'!I42 -> 191.9807 | I23: ='pivot tables'!J42 -> 220.47092 | J23: ='pivot tables'!K42 -> 238.97272 | ... AJ23: ='pivot tables'!AK42 -> 911.84214
B24: CHE | C24: ='pivot tables'!D43 -> 0 | D24: ='pivot tables'!E43 -> 0 | E24: ='pivot tables'!F43 -> 0 | F24: ='pivot tables'!G43 -> 0 | G24: ='pivot tables'!H43 -> 0 | H24: ='pivot tables'!I43 -> 0 | I24: ='pivot tables'!J43 -> 0 | J24: ='pivot tables'!K43 -> 0 | ... AJ24: ='pivot tables'!AK43 -> 0
B25: CZE | C25: ='pivot tables'!D44 -> 1472.6176 | D25: ='pivot tables'!E44 -> 1105.6059 | E25: ='pivot tables'!F44 -> 783.78008 | F25: ='pivot tables'!G44 -> 1044.9773 | G25: ='pivot tables'!H44 -> 1073.1232 | H25: ='pivot tables'!I44 -> 1179.9399 | I25: ='pivot tables'!J44 -> 1161.018 | J25: ='pivot tables'!K44 -> 1179.1346 | ... AJ25: ='pivot tables'!AK44 -> 1506.1559
B26: DEU | C26: ='pivot tables'!D45 -> 7114.3215 | D26: ='pivot tables'!E45 -> 6659.1367 | E26: ='pivot tables'!F45 -> 6857.3205 | F26: ='pivot tables'!G45 -> 6672.0535 | G26: ='pivot tables'!H45 -> 7673.2887 | H26: ='pivot tables'!I45 -> 7799.0742 | I26: ='pivot tables'!J45 -> 8090.6236 | J26: ='pivot tables'!K45 -> 8289.9201 | ... AJ26: ='pivot tables'!AK45 -> 12371.871
B27: DNK | C27: ='pivot tables'!D46 -> 145.02104 | D27: ='pivot tables'!E46 -> 109.50607 | E27: ='pivot tables'!F46 -> 161.74843 | F27: ='pivot tables'!G46 -> 234.66788 | G27: ='pivot tables'!H46 -> 217.60276 | H27: ='pivot tables'!I46 -> 216.72923 | I27: ='pivot tables'!J46 -> 229.29324 | J27: ='pivot tables'!K46 -> 204.05639 | ... AJ27: ='pivot tables'!AK46 -> 180.63831
B28: ESP | C28: ='pivot tables'!D47/1000 -> 1975.5827 | D28: ='pivot tables'!E47/1000 -> 2018.2265 | E28: ='pivot tables'!F47/1000 -> 1708.1349 | F28: ='pivot tables'!G47/1000 -> 1866.5006 | G28: ='pivot tables'!H47/1000 -> 1923.5688 | H28: ='pivot tables'!I47/1000 -> 2031.837 | I28: ='pivot tables'!J47/1000 -> 2016.0075 | J28: ='pivot tables'!K47/1000 -> 1962.7625 | ... AJ28: ='pivot tables'!AK47/1000 -> 2780.5542
B29: EST | C29: ='pivot tables'!D48 -> 184.15402 | D29: ='pivot tables'!E48 -> 148.23175 | E29: ='pivot tables'!F48 -> 112.30947 | F29: ='pivot tables'!G48 -> 124.85033 | G29: ='pivot tables'!H48 -> 135.75525 | H29: ='pivot tables'!I48 -> 148.70835 | I29: ='pivot tables'!J48 -> 182.17374 | J29: ='pivot tables'!K48 -> 255.56088 | ... AJ29: ='pivot tables'!AK48 -> 465.22437
B30: FIN | C30: ='pivot tables'!D49 -> 5353.914 | D30: ='pivot tables'!E49 -> 4884.26 | E30: ='pivot tables'!F49 -> 4995.434 | F30: ='pivot tables'!G49 -> 5686.788 | G30: ='pivot tables'!H49 -> 6236.111 | H30: ='pivot tables'!I49 -> 6216.394 | I30: ='pivot tables'!J49 -> 6086.438 | J30: ='pivot tables'!K49 -> 6950.088 | ... AJ30: ='pivot tables'!AK49 -> 6357.943
B31: FRA | C31: ='pivot tables'!D50/1000 -> 4507.2017 | D31: ='pivot tables'!E50/1000 -> 4472.8381 | E31: ='pivot tables'!F50/1000 -> 3962.7974 | F31: ='pivot tables'!G50/1000 -> 3637.9092 | G31: ='pivot tables'!H50/1000 -> 3913.7158 | H31: ='pivot tables'!I50/1000 -> 4054.7089 | I31: ='pivot tables'!J50/1000 -> 3919.7119 | J31: ='pivot tables'!K50/1000 -> 4115.026 | ... AJ31: ='pivot tables'!AK50/1000 -> 3721.8437
B32: GBR | C32: ='pivot tables'!D51 -> 1191.382 | D32: ='pivot tables'!E51 -> 1171.4077 | E32: ='pivot tables'!F51 -> 1202.4284 | F32: ='pivot tables'!G51 -> 1230.4538 | G32: ='pivot tables'!H51 -> 1319.2954 | H32: ='pivot tables'!I51 -> 1361.1506 | I32: ='pivot tables'!J51 -> 1364.1563 | J32: ='pivot tables'!K51 -> 1429.5223 | ... AJ32: ='pivot tables'!AK51 -> 1644.9336
B33: GRC | C33: ='pivot tables'!D52/1000 -> 175.69457 | D33: ='pivot tables'!E52/1000 -> 177.65716 | E33: ='pivot tables'!F52/1000 -> 152.10628 | F33: ='pivot tables'!G52/1000 -> 220.61445 | G33: ='pivot tables'!H52/1000 -> 227.25979 | H33: ='pivot tables'!I52/1000 -> 217.88213 | I33: ='pivot tables'!J52/1000 -> 229.17741 | J33: ='pivot tables'!K52/1000 -> 70.018648 | ... AJ33: ='pivot tables'!AK52/1000 -> 102.0673
B34: HRV | C34: ='pivot tables'!D53 -> 423.81014 | D34: ='pivot tables'!E53 -> 274.88284 | E34: ='pivot tables'!F53 -> 225.66389 | F34: ='pivot tables'!G53 -> 248.6722 | G34: ='pivot tables'!H53 -> 267.96886 | H34: ='pivot tables'!I53 -> 272.14443 | I34: ='pivot tables'!J53 -> 262.98001 | J34: ='pivot tables'!K53 -> 221.36977 | ... AJ34: ='pivot tables'!AK53 -> 442.07326
B35: IRL | C35: ='pivot tables'!D54 -> 150.00993 | D35: ='pivot tables'!E54 -> 151.54259 | E35: ='pivot tables'!F54 -> 195.60469 | F35: ='pivot tables'!G54 -> 206.02904 | G35: ='pivot tables'!H54 -> 225.85368 | H35: ='pivot tables'!I54 -> 239.09194 | I35: ='pivot tables'!J54 -> 273.65057 | J35: ='pivot tables'!K54 -> 279.83418 | ... AJ35: ='pivot tables'!AK54 -> 456.7898
B36: ITA | C36: ='pivot tables'!D55 -> 804.49517 | D36: ='pivot tables'!E55 -> 712.28063 | E36: ='pivot tables'!F55 -> 612.25705 | F36: ='pivot tables'!G55 -> 694.34762 | G36: ='pivot tables'!H55 -> 608.28509 | H36: ='pivot tables'!I55 -> 838.89111 | I36: ='pivot tables'!J55 -> 871.76862 | J36: ='pivot tables'!K55 -> 851.24979 | ... AJ36: ='pivot tables'!AK55 -> 805.82458
B37: LTU | C37: ='pivot tables'!D56 -> 290.06299 | D37: ='pivot tables'!E56 -> 295.69639 | E37: ='pivot tables'!F56 -> 127.46243 | F37: ='pivot tables'!G56 -> 239.77167 | G37: ='pivot tables'!H56 -> 368.96596 | H37: ='pivot tables'!I56 -> 419.51114 | I37: ='pivot tables'!J56 -> 510.26268 | J37: ='pivot tables'!K56 -> 449.53498 | ... AJ37: ='pivot tables'!AK56 -> 884.48822
B38: LVA | C38: ='pivot tables'!D57 -> 315.69554 | D38: ='pivot tables'!E57 -> 315.69554 | E38: ='pivot tables'!F57 -> 258.04735 | F38: ='pivot tables'!G57 -> 164.0275 | G38: ='pivot tables'!H57 -> 296.40003 | H38: ='pivot tables'!I57 -> 399.97042 | I38: ='pivot tables'!J57 -> 460.0324 | J38: ='pivot tables'!K57 -> 706.47613 | ... AJ38: ='pivot tables'!AK57 -> 1217.1913
B39: NOR | C39: ='pivot tables'!D58 -> 1431.66 | D39: ='pivot tables'!E58 -> 1360.73 | E39: ='pivot tables'!F58 -> 1340.89 | F39: ='pivot tables'!G58 -> 1420.7 | G39: ='pivot tables'!H58 -> 1535.5 | H39: ='pivot tables'!I58 -> 1529.48 | I39: ='pivot tables'!J58 -> 1509.57 | J39: ='pivot tables'!K58 -> 1541.72 | ... AJ39: ='pivot tables'!AK58 -> 1066.51
B40: POL | C40: ='pivot tables'!D59 -> 518.61845 | D40: ='pivot tables'!E59 -> 477.93485 | E40: ='pivot tables'!F59 -> 572.37339 | F40: ='pivot tables'!G59 -> 652.68964 | G40: ='pivot tables'!H59 -> 760.94607 | H40: ='pivot tables'!I59 -> 687.50174 | I40: ='pivot tables'!J59 -> 675.89992 | J40: ='pivot tables'!K59 -> 775.90317 | ... AJ40: ='pivot tables'!AK59 -> 2426.9252
B41: PRT | C41: ='pivot tables'!D60/1000 -> 1231.7469 | D41: ='pivot tables'!E60/1000 -> 1225.9837 | E41: ='pivot tables'!F60/1000 -> 1145.2431 | F41: ='pivot tables'!G60/1000 -> 1115.2372 | G41: ='pivot tables'!H60/1000 -> 1110.9834 | H41: ='pivot tables'!I60/1000 -> 1076.5982 | I41: ='pivot tables'!J60/1000 -> 1129.5924 | J41: ='pivot tables'!K60/1000 -> 1068.9623 | ... AJ41: ='pivot tables'!AK60/1000 -> 1261.3552
B42: ROU | C42: ='pivot tables'!D61 -> 1187.4061 | D42: ='pivot tables'!E61 -> 904.00348 | E42: ='pivot tables'!F61 -> 979.16189 | F42: ='pivot tables'!G61 -> 989.93313 | G42: ='pivot tables'!H61 -> 654.09947 | H42: ='pivot tables'!I61 -> 702.67975 | I42: ='pivot tables'!J61 -> 668.35991 | J42: ='pivot tables'!K61 -> 696.08884 | ... AJ42: ='pivot tables'!AK61 -> 1798.1314
B43: SVK | C43: ='pivot tables'!D62/1000 -> 445.37388 | D43: ='pivot tables'!E62/1000 -> 335.83904 | E43: ='pivot tables'!F62/1000 -> 239.53126 | F43: ='pivot tables'!G62/1000 -> 304.95126 | G43: ='pivot tables'!H62/1000 -> 345.84498 | H43: ='pivot tables'!I62/1000 -> 338.02633 | I43: ='pivot tables'!J62/1000 -> 371.11552 | J43: ='pivot tables'!K62/1000 -> 429.55252 | ... AJ43: ='pivot tables'!AK62/1000 -> 630.41542
B44: SVN | C44: ='pivot tables'!D63 -> 215.3553 | D44: ='pivot tables'!E63 -> 182.61417 | E44: ='pivot tables'!F63 -> 167.64169 | F44: ='pivot tables'!G63 -> 154.69872 | G44: ='pivot tables'!H63 -> 167.45346 | H44: ='pivot tables'!I63 -> 170.60401 | I44: ='pivot tables'!J63 -> 189.6607 | J44: ='pivot tables'!K63 -> 171.9785 | ... AJ44: ='pivot tables'!AK63 -> 267.96023
B45: SWE | C45: ='pivot tables'!D64/1000 -> 9144.959 | D45: ='pivot tables'!E64/1000 -> 9097.595 | E45: ='pivot tables'!F64/1000 -> 9022.94 | F45: ='pivot tables'!G64/1000 -> 9589.762 | G45: ='pivot tables'!H64/1000 -> 9857.729 | H45: ='pivot tables'!I64/1000 -> 10137.078 | I45: ='pivot tables'!J64/1000 -> 10103.451 | J45: ='pivot tables'!K64/1000 -> 10774.961 | ... AJ45: ='pivot tables'!AK64/1000 -> 17806.518
B52: LivingBMLosses(ktC)
B53: Country | C53: 1990 | D53: 1991 | E53: 1992 | F53: 1993 | G53: 1994 | H53: 1995 | I53: 1996 | J53: 1997 | K53: 1998 | L53: 1999 | M53: 2000 | N53: 2001 | O53: 2002 | P53: 2003 | Q53: 2004 | R53: 2005 | S53: 2006 | T53: 2007 | U53: 2008 | V53: 2009 | W53: 2010 | X53: 2011 | Y53: 2012 | Z53: 2013 | AA53: 2014 | AB53: 2015 | AC53: 2016 | AD53: 2017 | AE53: 2018 | AF53: 2019 | AG53: 2020 | AH53: 2021 | AI53: 2022 | AJ53: 2023
B54: AUT | C54: ='pivot tables'!D106 -> -6976.4549 | D54: ='pivot tables'!E106 -> -5109.0566 | E54: ='pivot tables'!F106 -> -5458.791 | F54: ='pivot tables'!G106 -> -5440.9023 | G54: ='pivot tables'!H106 -> -6351.2919 | H54: ='pivot tables'!I106 -> -5727.7128 | I54: ='pivot tables'!J106 -> -6197.4497 | J54: ='pivot tables'!K106 -> -6089.2939 | ... AJ54: ='pivot tables'!AK106 -> -10000.194
B55: BEL | C55: ='pivot tables'!D107 -> -1.4117948 | D55: ='pivot tables'!E107 -> -1.4130476 | E55: ='pivot tables'!F107 -> -1.4146968 | F55: ='pivot tables'!G107 -> -1.4157421 | G55: ='pivot tables'!H107 -> -1.4165717 | H55: ='pivot tables'!I107 -> -1.4172198 | I55: ='pivot tables'!J107 -> -1.4178762 | J55: ='pivot tables'!K107 -> -1.4189397 | ... AJ55: ='pivot tables'!AK107 -> -5.734042
B56: BGR | C56: ='pivot tables'!D108 -> -25.634676 | D56: ='pivot tables'!E108 -> -26.295097 | E56: ='pivot tables'!F108 -> -26.937083 | F56: ='pivot tables'!G108 -> -25.278121 | G56: ='pivot tables'!H108 -> -25.356123 | H56: ='pivot tables'!I108 -> -24.598757 | I56: ='pivot tables'!J108 -> -24.53441 | J56: ='pivot tables'!K108 -> -24.392008 | ... AJ56: ='pivot tables'!AK108 -> -76.453977
...

Sheet pivot tables
A1: pivot tables
C5: Summe von TotalArea(kha) | D5: Spaltenbeschriftungen
C6: Zeilenbeschriftungen | D6: 1990 | E6: 1991 | F6: 1992 | G6: 1993 | H6: 1994 | I6: 1995 | J6: 1996 | K6: 1997 | L6: 1998 | M6: 1999 | N6: 2000 | O6: 2001 | P6: 2002 | Q6: 2003 | R6: 2004 | S6: 2005 | T6: 2006 | U6: 2007 | V6: 2008 | W6: 2009 | X6: 2010 | Y6: 2011 | Z6: 2012 | AA6: 2013 | AB6: 2014 | AC6: 2015 | AD6: 2016 | AE6: 2017 | AF6: 2018 | AG6: 2019 | AH6: 2020 | AI6: 2021 | AJ6: 2022 | AK6: 2023
C7: AUT | D7: 3892.5179 | E7: 3900.1819 | F7: 3907.846 | G7: 3915.51 | H7: 3923.1741 | I7: 3928.4501 | J7: 3933.7261 | K7: 3939.0021 | L7: 3944.2782 | M7: 3949.5542 | N7: 3954.8302 | O7: 3960.1062 | P7: 3964.3637 | Q7: 3968.6212 | R7: 3972.8786 | S7: 3977.1361 | T7: 3981.3935 | U7: 3985.651 | V7: 3989.9085 | W7: 3992.1895 | X7: 3994.4706 | Y7: 3996.7516 | Z7: 3999.0327 | AA7: 4001.3137 | AB7: 4003.5948 | AC7: 4005.8758 | AD7: 4008.1569 | AE7: 4010.4379 | AF7: 4012.719 | AG7: 4015 | AH7: 4017.281 | AI7: 4019.5621 | AJ7: 4021.8431 | AK7: 4024.1242
C8: BEL | D8: 708.60066 | E8: 708.93429 | F8: 709.26792 | G8: 709.60154 | H8: 709.93517 | I8: 710.2688 | J8: 710.60243 | K8: 710.94319 | L8: 711.28396 | M8: 711.62473 | N8: 711.96549 | O8: 712.30626 | P8: 712.64703 | Q8: 712.98779 | R8: 713.32856 | S8: 713.64434 | T8: 713.96012 | U8: 714.27589 | V8: 714.59167 | W8: 714.93244 | X8: 715.58689 | Y8: 716.24134 | Z8: 716.89579 | AA8: 716.88222 | AB8: 716.86865 | AC8: 716.85508 | AD8: 717.17552 | AE8: 717.49596 | AF8: 717.8164 | AG8: 718.13684 | AH8: 718.45728 | AI8: 718.77772 | AJ8: 719.09816 | AK8: 719.4186
C9: BGR | D9: 3809.2573 | E9: 3813.422 | F9: 3817.5868 | G9: 3821.7515 | H9: 3825.9162 | I9: 3830.081 | J9: 3834.2457 | K9: 3838.4104 | L9: 3842.5752 | M9: 3846.7399 | N9: 3850.9046 | O9: 3855.0693 | P9: 3859.2341 | Q9: 3863.3988 | R9: 3867.5635 | S9: 3871.7283 | T9: 3875.893 | U9: 3880.0577 | V9: 3884.2225 | W9: 3888.3872 | X9: 3892.5519 | Y9: 3895.2087 | Z9: 3897.8655 | AA9: 3900.5224 | AB9: 3903.1792 | AC9: 3905.836 | AD9: 3908.4928 | AE9: 3911.1496 | AF9: 3913.8064 | AG9: 3916.4632 | AH9: 3919.12 | AI9: 3920.6291 | AJ9: 3925.3087 | AK9: 3933.455
C10: CHE | D10: 1214.98 | E10: 1217.245 | F10: 1219.556 | G10: 1221.721 | H10: 1223.606 | I10: 1225.416 | J10: 1226.97 | K10: 1228.513 | L10: 1229.629 | M10: 1230.855 | N10: 1231.88 | O10: 1233.314 | P10: 1234.32 | Q10: 1235.687 | R10: 1236.848 | S10: 1238.136 | T10: 1239.301 | U10: 1240.579 | V10: 1242.216 | W10: 1244.098 | X10: 1246.055 | Y10: 1247.969 | Z10: 1250.051 | AA10: 1251.864 | AB10: 1253.762 | AC10: 1255.986 | AD10: 1258.224 | AE10: 1260.295 | AF10: 1262.32 | AG10: 1264.293 | AH10: 1265.759 | AI10: 1267.181 | AJ10: 1268.59 | AK10: 1270.002
C11: CZE | D11: 2629.483 | E11: 2629.295 | F11: 2629.075 | G11: 2628.6289 | H11: 2629.5015 | I11: 2630.1282 | J11: 2630.9928 | K11: 2631.8035 | L11: 2633.819 | M11: 2634.4717 | N11: 2637.2897 | O11: 2639.1597 | P11: 2643.0566 | Q11: 2644.17 | R11: 2645.7401 | S11: 2647.4183 | T11: 2649.1494 | U11: 2651.2102 | V11: 2653.0349 | W11: 2655.2114 | X11: 2657.3759 | Y11: 2659.8384 | Z11: 2661.8893 | AA11: 2663.7305 | AB11: 2666.3764 | AC11: 2668.3922 | AD11: 2669.8498 | AE11: 2671.6585 | AF11: 2673.3917 | AG11: 2675.6699 | AH11: 2677.329 | AI11: 2678.8041 | AJ11: 2680.372 | AK11: 2681.7637
C12: DEU | D12: 10673.067 | E12: 10683.56 | F12: 10694.045 | G12: 10704.522 | H12: 10714.992 | I12: 10725.457 | J12: 10735.921 | K12: 10746.379 | L12: 10756.83 | M12: 10767.273 | N12: 10777.714 | O12: 10779.374 | P12: 10781.008 | Q12: 10782.622 | R12: 10784.228 | S12: 10785.818 | T12: 10790.109 | U12: 10794.354 | V12: 10798.567 | W12: 10802.755 | X12: 10806.925 | Y12: 10809.583 | Z12: 10812.225 | AA12: 10814.854 | AB12: 10817.472 | AC12: 10820.072 | AD12: 10828.324 | AE12: 10836.562 | AF12: 10844.775 | AG12: 10852.975 | AH12: 10861.162 | AI12: 10868.209 | AJ12: 10875.236 | AK12: 10882.244
C13: DNK | D13: 546.4406 | E13: 550.7705 | F13: 555.27362 | G13: 559.77675 | H13: 564.27987 | I13: 568.783 | J13: 573.28613 | K13: 577.78925 | L13: 582.29238 | M13: 586.7955 | N13: 591.29863 | O13: 595.80175 | P13: 600.30488 | Q13: 604.808 | R13: 609.31113 | S13: 613.81425 | T13: 618.40535 | U13: 622.99646 | V13: 627.58756 | W13: 632.17867 | X13: 636.76977 | Y13: 641.36087 | Z13: 643.565 | AA13: 648.5305 | AB13: 649.40581 | AC13: 652.12237 | AD13: 653.33912 | AE13: 654.9015 | AF13: 656.40387 | AG13: 657.78231 | AH13: 659.593 | AI13: 664.62519 | AJ13: 666.02631 | AK13: 666.631
C14: ESP | D14: 14200.431 | E14: 14326.378 | F14: 14452.325 | G14: 14578.272 | H14: 14704.219 | I14: 14830.166 | J14: 14956.114 | K14: 15082.061 | L14: 15208.008 | M14: 15333.955 | N14: 15459.902 | O14: 15617.65 | P14: 15775.399 | Q14: 15933.147 | R14: 16090.895 | S14: 16248.644 | T14: 16406.392 | U14: 16516.326 | V14: 16626.261 | W14: 16736.196 | X14: 16900.454 | Y14: 17064.713 | Z14: 17228.971 | AA14: 17388.94 | AB14: 17548.909 | AC14: 17708.878 | AD14: 17797.578 | AE14: 17886.277 | AF14: 17974.977 | AG14: 18003.984 | AH14: 18032.991 | AI14: 18061.998 | AJ14: 18091.005 | AK14: 18120.012
C15: EST | D15: 2368.686 | E15: 2371.512 | F15: 2375.407 | G15: 2380.391 | H15: 2385.376 | I15: 2390.755 | J15: 2396.528 | K15: 2402.538 | L15: 2408.244 | M15: 2414.329 | N15: 2419.889 | O15: 2424.201 | P15: 2427.764 | Q15: 2431.552 | R15: 2434.821 | S15: 2437.857 | T15: 2440.476 | U15: 2442.684 | V15: 2444.164 | W15: 2445.124 | X15: 2445.877 | Y15: 2447.023 | Z15: 2448.218 | AA15: 2449.229 | AB15: 2449.911 | AC15: 2450.238 | AD15: 2450.242 | AE15: 2449.977 | AF15: 2450.315 | AG15: 2451.001 | AH15: 2452.02 | AI15: 2453.009 | AJ15: 2453.931 | AK15: 2454.152
C16: FIN | D16: 22108.644 | E16: 22115.154 | F16: 22120.336 | G16: 22122.665 | H16: 22124.978 | I16: 22126.139 | J16: 22126.404 | K16: 22123.704 | L16: 22120.612 | M16: 22114.673 | N16: 22105.77 | O16: 22093.177 | P16: 22078.83 | Q16: 22062.079 | R16: 22044.087 | S16: 22025.68 | T16: 22008.425 | U16: 21991.575 | V16: 21975.692 | W16: 21959.252 | X16: 21943.278 | Y16: 21928.208 | Z16: 21915.604 | AA16: 21904.489 | AB16: 21894.478 | AC16: 21886.747 | AD16: 21879.946 | AE16: 21873.307 | AF16: 21866.081 | AG16: 21860.085 | AH16: 21853.597 | AI16: 21847.304 | AJ16: 21840.691 | AK16: 21834.684
C17: FRA | D17: 23624.149 | E17: 23691.975 | F17: 23759.977 | G17: 23828.218 | H17: 23896.906 | I17: 23965.223 | J17: 24033.733 | K17: 24101.529 | L17: 24170.332 | M17: 24239.149 | N17: 24308.102 | O17: 24377.778 | P17: 24447.807 | Q17: 24517.774 | R17: 24588.003 | S17: 24658.539 | T17: 24728.848 | U17: 24792.548 | V17: 24856.31 | W17: 24921.011 | X17: 24984.639 | Y17: 25048.223 | Z17: 25111.388 | AA17: 25176.022 | AB17: 25241.213 | AC17: 25306.277 | AD17: 25372.093 | AE17: 25438.469 | AF17: 25505.586 | AG17: 25576.532 | AH17: 25647.366 | AI17: 25718.225 | AJ17: 25789.344 | AK17: 25860.262
... C32: Gesamtergebnis | D32: 171011 | E32: 171414.09 | F32: 171813.41 | G32: 172199.58 | H32: 172605.71 | I32: 173011.05 | J32: 173451.9 | K32: 173865.33 | L32: 174302.96 | M32: 174705.05 | N32: 175114.38 | O32: 175515.58 | P32: 175950.87 | Q32: 176372.66 | R32: 176800.41 | S32: 177204.84 | T32: 177549.5 | U32: 177880.01 | V32: 178164.01 | W32: 178441.42 | X32: 178786.63 | Y32: 179148.01 | Z32: 179501.48 | AA32: 179842.12 | AB32: 180163.3 | AC32: 180488.38 | AD32: 180840.73 | AE32: 181269.64 | AF32: 181658.06 | AG32: 181998.49 | AH32: 182324.45 | AI32: 182726.83 | AJ32: 183129.21 | AK32: 183493.38
C38: Summe von HWP in use from domestic harvest (kt C) | D38: Spaltenbeschriftungen
C39: Zeilenbeschriftungen | D39: 1990 | E39: 1991 | F39: 1992 | G39: 1993 | H39: 1994 | I39: 1995 | J39: 1996 | K39: 1997 | L39: 1998 | M39: 1999 | N39: 2000 | O39: 2001 | P39: 2002 | Q39: 2003 | R39: 2004 | S39: 2005 | T39: 2006 | U39: 2007 | V39: 2008 | W39: 2009 | X39: 2010 | Y39: 2011 | Z39: 2012 | AA39: 2013 | AB39: 2014 | AC39: 2015 | AD39: 2016 | AE39: 2017 | AF39: 2018 | AG39: 2019 | AH39: 2020 | AI39: 2021 | AJ39: 2022 | AK39: 2023
C40: AUT | D40: 2434.6331 | E40: 2192.7339 | F40: 2144.2568 | G40: 2115.4447 | H40: 2401.4302 | I40: 2431.8994 | J40: 2576.1843 | K40: 2532.8888 | L40: 2535.2699 | M40: 2367.8541 | N40: 2350.8866 | O40: 2583.1912 | P40: 2870.7109 | Q40: 3087.9703 | R40: 2928.8893 | S40: 2971.7204 | T40: 3113.1908 | U40: 3518.006 | V40: 3513.171 | W40: 2542.0164 | X40: 2900.9499 | Y40: 2987.883 | Z40: 2832.5211 | AA40: 2577.864 | AB40: 2629.0778 | AC40: 2588.2772 | AD40: 2544.3233 | AE40: 2697.8241 | AF40: 2777.1929 | AG40: 2650.8696 | AH40: 2266.1232 | AI40: 2743.8761 | AJ40: 2799.2129 | AK40: 2439.2184
C41: BEL | D41: 707660.53 | E41: 607999.59 | F41: 574435.9 | G41: 590775.57 | H41: 534910.4 | I41: 610101.87 | J41: 678755.25 | K41: 563270.97 | L41: 726042.08 | M41: 593641.99 | N41: 465194.47 | O41: 407163.32 | P41: 599092.42 | Q41: 573143.13 | R41: 538216.18 | S41: 563168.4 | T41: 562700 | U41: 485211.99 | V41: 471309.75 | W41: 428333.96 | X41: 356143.05 | Y41: 343204.85 | Z41: 338563.45 | AA41: 379575.97 | AB41: 392171.34 | AC41: 407206.85 | AD41: 402428.59 | AE41: 368027.13 | AF41: 366481.81 | AG41: 335151.27 | AH41: 332282.3 | AI41: 316510.54 | AJ41: 367347.27 | AK41: 311796.7
C42: BGR | D42: 451.87986 | E42: 417.03694 | F42: 209.59836 | G42: 179.68791 | H42: 184.53622 | I42: 191.9807 | J42: 220.47092 | K42: 238.97272 | L42: 216.20317 | M42: 275.6123 | N42: 348.65891 | O42: 370.78757 | P42: 411.45926 | Q42: 407.97076 | R42: 541.7899 | S42: 595.96875 | T42: 597.90055 | U42: 835.96569 | V42: 631.68311 | W42: 622.41152 | X42: 652.90107 | Y42: 748.75847 | Z42: 750.23387 | AA42: 733.75175 | AB42: 756.75754 | AC42: 845.82663 | AD42: 752.4708 | AE42: 831.20355 | AF42: 824.20126 | AG42: 788.03522 | AH42: 853.03895 | AI42: 865.71946 | AJ42: 827.33141 | AK42: 911.84214
C43: CHE | D43: 0 | E43: 0 | F43: 0 | G43: 0 | H43: 0 | I43: 0 | J43: 0 | K43: 0 | L43: 0 | M43: 0 | N43: 0 | O43: 0 | P43: 0 | Q43: 0 | R43: 0 | S43: 0 | T43: 0 | U43: 0 | V43: 0 | W43: 0 | X43: 0 | Y43: 0 | Z43: 0 | AA43: 0 | AB43: 0 | AC43: 0 | AD43: 0 | AE43: 0 | AF43: 0 | AG43: 0 | AH43: 0 | AI43: 0 | AJ43: 0 | AK43: 0
C44: CZE | D44: 1472.6176 | E44: 1105.6059 | F44: 783.78008 | G44: 1044.9773 | H44: 1073.1232 | I44: 1179.9399 | J44: 1161.018 | K44: 1179.1346 | L44: 1132.3679 | M44: 1170.5443 | N44: 1307.7642 | O44: 1302.0532 | P44: 1285.8458 | Q44: 1404.1169 | R44: 1438.0162 | S44: 1420.1712 | T44: 1705.7063 | U44: 1867.589 | V44: 1643.8999 | W44: 1370.1663 | X44: 1524.081 | Y44: 1345.1081 | Z44: 1267.5209 | AA44: 1099.3591 | AB44: 1072.6682 | AC44: 1174.0745 | AD44: 1267.6677 | AE44: 1346.4692 | AF44: 1461.3198 | AG44: 1584.4508 | AH44: 1874.3347 | AI44: 1788.3416 | AJ44: 1695.0364 | AK44: 1506.1559
C45: DEU | D45: 7114.3215 | E45: 6659.1367 | F45: 6857.3205 | G45: 6672.0535 | H45: 7673.2887 | I45: 7799.0742 | J45: 8090.6236 | K45: 8289.9201 | L45: 8639.2282 | M45: 8985.2097 | N45: 10067.122 | O45: 9971.7678 | P45: 10958.746 | Q45: 11410.562 | R45: 12682.802 | S45: 13871.262 | T45: 14054.668 | U45: 15335.568 | V45: 12937.726 | W45: 12350.546 | X45: 12395.262 | Y45: 12251.626 | Z45: 11843.481 | AA45: 11594.287 | AB45: 11727.473 | AC45: 11761.845 | AD45: 11710.214 | AE45: 11886.833 | AF45: 12521.579 | AG45: 12701.757 | AH45: 13190.013 | AI45: 13407.155 | AJ45: 12373.719 | AK45: 12371.871
C46: DNK | D46: 145.02104 | E46: 109.50607 | F46: 161.74843 | G46: 234.66788 | H46: 217.60276 | I46: 216.72923 | J46: 229.29324 | K46: 204.05639 | L46: 166.44842 | M46: 117.98411 | N46: 164.9458 | O46: 121.48854 | P46: 99.505869 | Q46: 102.12123 | R46: 95.518 | S46: 112.96627 | T46: 120.12433 | U46: 133.33673 | V46: 158.1964 | W46: 146.27957 | X46: 147.04216 | Y46: 168.71106 | Z46: 161.29377 | AA46: 167.12503 | AB46: 182.34197 | AC46: 190.23783 | AD46: 192.07783 | AE46: 190.06836 | AF46: 159.3275 | AG46: 170.39939 | AH46: 180.11634 | AI46: 163.91529 | AJ46: 175.86926 | AK46: 180.63831
C47: ESP | D47: 1975582.7 | E47: 2018226.5 | F47: 1708134.9 | G47: 1866500.6 | H47: 1923568.8 | I47: 2031837 | J47: 2016007.5 | K47: 1962762.5 | L47: 1809526.1 | M47: 2264935.4 | N47: 2434354.1 | O47: 2544883.7 | P47: 2642199.7 | Q47: 2687140.2 | R47: 2750312.6 | S47: 2661540.8 | T47: 2877469.8 | U47: 2632602.4 | V47: 2514998.3 | W47: 2019894.9 | X47: 1993501.6 | Y47: 1944984.1 | Z47: 1877314.8 | AA47: 1864058.6 | AB47: 2080880.5 | AC47: 2373623.5 | AD47: 2367699 | AE47: 2620220.2 | AF47: 2696693.9 | AG47: 2542202.6 | AH47: 2489006.2 | AI47: 2675528.6 | AJ47: 2780554.2 | AK47: 2780554.2
C48: EST | D48: 184.15402 | E48: 148.23175 | F48: 112.30947 | G48: 124.85033 | H48: 135.75525 | I48: 148.70835 | J48: 182.17374 | K48: 255.56088 | L48: 263.41144 | M48: 331.17695 | N48: 412.16661 | O48: 462.91007 | P48: 485.39094 | Q48: 477.47893 | R48: 406.12761 | S48: 351.04993 | T48: 360.74341 | U48: 322.00569 | V48: 355.37205 | W48: 361.16606 | X48: 466.28049 | Y48: 470.19861 | Z48: 434.02907 | AA48: 450.24643 | AB48: 478.21849 | AC48: 527.21937 | AD48: 559.3473 | AE48: 579.62263 | AF48: 597.71472 | AG48: 569.70841 | AH48: 563.7529 | AI48: 569.94913 | AJ48: 499.49542 | AK48: 465.22437
C49: FIN | D49: 5353.914 | E49: 4884.26 | F49: 4995.434 | G49: 5686.788 | H49: 6236.111 | I49: 6216.394 | J49: 6086.438 | K49: 6950.088 | L49: 7118.774 | M49: 7204.188 | N49: 7365.48 | O49: 6756.345 | P49: 6845.104 | Q49: 7015.002 | R49: 7158.265 | S49: 6187.257 | T49: 6939.363 | U49: 7288.176 | V49: 6281.302 | W49: 5213.534 | X49: 6174.272 | Y49: 6182.985 | Z49: 6044.601 | AA49: 6218.173 | AB49: 6399.641 | AC49: 6391.929 | AD49: 6693.275 | AE49: 6971.046 | AF49: 7107.226 | AG49: 6867.822 | AH49: 6260.379 | AI49: 6889.547 | AJ49: 6815.761 | AK49: 6357.943
C50: FRA | D50: 4507201.7 | E50: 4472838.1 | F50: 3962797.4 | G50: 3637909.2 | H50: 3913715.8 | I50: 4054708.9 | J50: 3919711.9 | K50: 4115026 | L50: 4308831.5 | M50: 4384006.9 | N50: 4601663 | O50: 4556581.1 | P50: 4251727.3 | Q50: 4225223.9 | R50: 4422663.9 | S50: 4638280.3 | T50: 4720348.5 | U50: 4885443.9 | V50: 4552774.7 | W50: 3955247.5 | X50: 4464697.8 | Y50: 4578288.3 | Z50: 4407569.9 | AA50: 4266445.5 | AB50: 4201185 | AC50: 4040693.8 | AD50: 3933458.8 | AE50: 3934361.3 | AF50: 3896284.3 | AG50: 3788063 | AH50: 3404609.1 | AI50: 4067050.8 | AJ50: 3929278.4 | AK50: 3721843.7
... C65: Gesamtergebnis | D65: 18211904 | E65: 17957502 | F65: 16826135 | G65: 17347810 | H65: 17938139 | I65: 18491038 | J65: 18473144 | K65: 19011328 | L65: 19358023 | M65: 20083161 | N65: 21044357 | O65: 20692772 | P65: 21264698 | Q65: 21889317 | R65: 22714442 | S65: 24046904 | T65: 25114907 | U65: 25563616 | V65: 24887015 | W65: 23448239 | X65: 24097001 | Y65: 24271126 | Z65: 24102431 | AA65: 23944193 | AB65: 24924948 | AC65: 25522151 | AD65: 25974752 | AE65: 26067218 | AF65: 26111265 | AG65: 26172723 | AH65: 26183234 | AI65: 27444241 | AJ65: 27445769 | AK65: 26649794
C71: Summe von LivinBMLosses(tC/ha) | D71: Spaltenbeschriftungen
C72: Zeilenbeschriftungen | D72: 1990 | E72: 1991 | F72: 1992 | G72: 1993 | H72: 1994 | I72: 1995 | J72: 1996 | K72: 1997 | L72: 1998 | M72: 1999 | N72: 2000 | O72: 2001 | P72: 2002 | Q72: 2003 | R72: 2004 | S72: 2005 | T72: 2006 | U72: 2007 | V72: 2008 | W72: 2009 | X72: 2010 | Y72: 2011 | Z72: 2012 | AA72: 2013 | AB72: 2014 | AC72: 2015 | AD72: 2016 | AE72: 2017 | AF72: 2018 | AG72: 2019 | AH72: 2020 | AI72: 2021 | AJ72: 2022 | AK72: 2023
C73: AUT | D73: -1.7922731 | E73: -1.3099534 | F73: -1.3968798 | G73: -1.3895769 | H73: -1.6189167 | I73: -1.4580083 | J73: -1.5754655 | K73: -1.5458976 | L73: -1.4717079 | M73: -1.4742852 | N73: -1.3872888 | O73: -1.4062833 | P73: -1.6986822 | Q73: -1.9365519 | R73: -1.8759044 | S73: -1.8726163 | T73: -2.1681783 | U73: -2.3963373 | V73: -2.4534967 | W73: -1.9190792 | X73: -2.0341847 | Y73: -2.1465945 | Z73: -2.0767642 | AA73: -2.0021182 | AB73: -1.9773133 | AC73: -2.0520409 | AD73: -1.9610585 | AE73: -2.0641915 | AF73: -2.2391827 | AG73: -2.4641097 | AH73: -2.1971674 | AI73: -2.3933134 | AJ73: -2.5275666 | AK73: -2.4850611
C74: BEL | D74: -0.0019923701 | E74: -0.0019931996 | F74: -0.0019945874 | G74: -0.0019951227 | H74: -0.0019953536 | I74: -0.0019953289 | J74: -0.0019953158 | K74: -0.0019958553 | L74: -0.0019973653 | M74: -0.0019970112 | N74: -0.0019960865 | O74: -0.0019954466 | P74: -0.0019954771 | Q74: -0.0019952451 | R74: -0.0019948053 | S74: -0.0019928798 | T74: -0.0019914722 | U74: -0.0019910504 | V74: -0.0019915021 | W74: -0.001991312 | X74: -0.0080128432 | Y74: -0.0080055807 | Z74: -0.0079981105 | AA74: -0.0079981031 | AB74: -0.0079984938 | AC74: -0.0079982823 | AD74: -0.0079953358 | AE74: -0.0079917411 | AF74: -0.0079881735 | AG74: -0.0079846091 | AH74: -0.0079810479 | AI74: -0.0079774898 | AJ74: -0.007973935 | AK74: -0.0079703832
C75: BGR | D75: -0.0067295732 | E75: -0.0068954071 | F75: -0.00705605 | G75: -0.0066142764 | H75: -0.0066274644 | I75: -0.0064225161 | J75: -0.0063987579 | K75: -0.0063547161 | L75: -0.0064274788 | M75: -0.0066140062 | N75: -0.006526225 | O75: -0.0063493375 | P75: -0.0064902906 | Q75: -0.0064060936 | R75: -0.0063989423 | S75: -0.0065892089 | T75: -0.0064931498 | U75: -0.0067189312 | V75: -0.0076855027 | W75: -0.0062961976 | X75: -0.0066661969 | Y75: -0.0063211609 | Z75: -0.0065357881 | AA75: -0.0069515591 | AB75: -0.0063522455 | AC75: -0.0071811882 | AD75: -0.0069483104 | AE75: -0.006998195 | AF75: -0.0063327862 | AG75: -0.0073038588 | AH75: -0.0065009121 | AI75: -0.0036484946 | AJ75: -0.010827327 | AK75: -0.01943685
C76: CHE | D76: -2.5217383 | E76: -1.9588196 | F76: -1.9445646 | G76: -1.9082518 | H76: -1.9917938 | I76: -2.0217374 | J76: -2.0346716 | K76: -2.1667945 | L76: -2.339046 | M76: -2.292453 | N76: -3.8348121 | O76: -2.5810936 | P76: -2.1949486 | Q76: -2.3834392 | R76: -2.3981707 | S76: -2.461848 | T76: -2.6838562 | U76: -2.6794991 | V76: -2.5171648 | W76: -2.3697565 | X76: -2.4658463 | Y76: -2.445395 | Z76: -2.2831681 | AA76: -2.3305665 | AB76: -2.3819347 | AC76: -2.2415416 | AD76: -2.2048297 | AE76: -2.2902356 | AF76: -2.6477631 | AG76: -2.4362463 | AH76: -2.4930441 | AI76: -2.5710227 | AJ76: -2.6502785 | AK76: -2.5493867
C77: CZE | D77: -1.7966858 | E77: -1.4623637 | F77: -1.3608743 | G77: -1.3636478 | H77: -1.5849969 | I77: -1.6692405 | J77: -1.6942196 | K77: -1.8431343 | L77: -1.8682184 | M77: -1.9028276 | N77: -1.9381952 | O77: -1.9196976 | P77: -1.924357 | Q77: -1.9868409 | R77: -2.0446289 | S77: -2.0262071 | T77: -2.3051708 | U77: -2.393384 | V77: -2.0975294 | W77: -2.0068069 | X77: -2.1646317 | Y77: -1.9609467 | Z77: -1.940077 | AA77: -1.9686338 | AB77: -1.9790769 | AC77: -2.0566308 | AD77: -2.2204902 | AE77: -2.4303312 | AF77: -3.198429 | AG77: -4.014791 | AH77: -4.3640583 | AI77: -3.7079641 | AJ77: -3.1230057 | AK77: -2.3331286
C78: DEU | D78: -0.027627629 | E78: -0.027232988 | F78: -0.027353505 | G78: -0.027678426 | H78: -0.027471552 | I78: -0.027717922 | J78: -0.027636599 | K78: -0.027627842 | L78: -0.027577059 | M78: -0.027412789 | N78: -0.027564783 | O78: -0.028800486 | P78: -0.028951533 | Q78: -0.028543968 | R78: -0.028957211 | S78: -0.029048909 | T78: -0.024015435 | U78: -0.024632555 | V78: -0.025498328 | W78: -0.027017881 | X78: -0.028301682 | Y78: -0.019862494 | Z78: -0.021526881 | AA78: -0.022827364 | AB78: -0.023482033 | AC78: -0.024558002 | AD78: -0.044316765 | AE78: -0.045795536 | AF78: -0.84437364 | AG78: -0.82091575 | AH78: -0.91250768 | AI78: -0.83279995 | AJ78: -0.80160076 | AK78: -0.66469133
C79: DNK | D79: -0.055075459 | E79: -0.032397663 | F79: -0.032122403 | G79: -0.031851571 | H79: -0.03073584 | I79: -0.028630576 | J79: -0.028405684 | K79: -0.028184298 | L79: -0.027966337 | M79: -0.02775172 | N79: -0.027708094 | O79: -0.027498674 | P79: -0.027292396 | Q79: -0.027089189 | R79: -0.026888986 | S79: -0.027776653 | T79: -0.037554889 | U79: -0.046089399 | V79: -0.05449904 | W79: -0.062786534 | X79: -0.069908701 | Y79: -0.069408268 | Z79: -0.07698972 | AA79: -0.064697527 | AB79: -0.060321722 | AC79: -0.072409911 | AD79: -0.067554891 | AE79: -0.064176943 | AF79: -0.066366556 | AG79: -0.061557652 | AH79: -0.070696969 | AI79: -0.080329454 | AJ79: -0.066514078 | AK79: -0.072552399
C80: ESP | D80: 0 | E80: 0 | F80: 0 | G80: 0 | H80: 0 | I80: 0 | J80: 0 | K80: 0 | L80: 0 | M80: 0 | N80: 0 | O80: 0 | P80: 0 | Q80: 0 | R80: 0 | S80: 0 | T80: 0 | U80: 0 | V80: 0 | W80: 0 | X80: 0 | Y80: 0 | Z80: 0 | AA80: 0 | AB80: 0 | AC80: 0 | AD80: 0 | AE80: 0 | AF80: 0 | AG80: 0 | AH80: 0 | AI80: 0 | AJ80: 0 | AK80: 0
C81: EST | D81: -0.081362895 | E81: -0.1024745 | F81: -0.12900614 | G81: -0.16233321 | H81: -0.20427071 | I81: -0.2570012 | J81: -0.32329202 | K81: -0.40664411 | L81: -0.51155406 | M81: -0.64343226 | N81: -0.80948929 | O81: -1.018932 | P81: -1.2829644 | Q81: -1.0558092 | R81: -0.97605829 | S81: -0.76736553 | T81: -0.63133164 | U81: -0.52428183 | V81: -0.52460407 | W81: -0.52300725 | X81: -0.71749348 | Y81: -1.0199468 | Z81: -1.1108067 | AA81: -1.2000705 | AB81: -1.185459 | AC81: -1.2080666 | AD81: -1.24918 | AE81: -1.2982933 | AF81: -1.4585328 | AG81: -1.427763 | AH81: -1.2015153 | AI81: -1.168428 | AJ81: -1.0830496 | AK81: -1.2729627
...

Sheet Table4.A FL
A1: country | B1: Year | C1: TotalArea(kha) | D1: MineralSoil(kha) | E1: OrganicSoil(kha) | F1: LivingBMGains(tC/ha) | G1: LivinBMLosses(tC/ha) | H1: LivingBMNetChange(tC/ha) | I1: DeadWoodNetChange(tC/ha) | J1: LitterNetChange(tC/ha) | K1: MineralSoilsNetChange(tC/ha) | L1: OrganicSoilsNetChange(tC/ha) | M1: LivingBMGains(ktC) | N1: LivingBMLosses(ktC) | O1: LivingBMNetChange(ktC) | P1: DeadwoodNetChange(ktC) | Q1: LitterNetChange(ktC) | R1: MineralSoilsNetChange(ktC) | S1: OrganicSoilsNetChange(ktC) | T1: NetCO2(ktCO2)
A2: AUT | B2: 1990 | C2: 3892.5179 | D2: 3850.9469 | E2: 41.571 | F2: 2.5654097 | G2: -1.7922731 | H2: 0.77313666 | I2: 0.017979689 | J2: 0.083187055 | K2: 0.093983565 | L2: NaN | M2: 9985.9031 | N2: -6976.4549 | O2: 3009.4483 | P2: 69.986262 | Q2: 323.8071 | R2: 361.92572 | S2: NaN | T2: -13805.614
A3: AUT | B3: 1991 | C3: 3900.1819 | D3: 3858.6109 | E3: 41.571 | F3: 2.4504963 | G3: -1.3099534 | H3: 1.1405429 | I3: 0.018069548 | J3: 0.086044741 | K3: 0.16624266 | L3: NaN | M3: 9557.3815 | N3: -5109.0566 | O3: 4448.3249 | P3: 70.474525 | Q3: 335.59014 | R3: 641.46573 | S3: NaN | T3: -20151.469
A4: AUT | B4: 1992 | C4: 3907.846 | D4: 3866.275 | E4: 41.571 | F4: 2.2925881 | G4: -1.3968798 | H4: 0.89570827 | I4: 0.018113975 | J4: 0.088891219 | K4: 0.03471962 | L4: NaN | M4: 8959.081 | N4: -5458.791 | O4: 3500.2899 | P4: 70.786626 | Q4: 347.37319 | R4: 134.2356 | S4: NaN | T4: -14859.846
A5: AUT | B5: 1993 | C5: 3915.51 | D5: 3873.939 | E5: 41.571 | F5: 2.2731188 | G5: -1.3895769 | H5: 0.88354185 | I5: 0.018118512 | J5: 0.091726553 | K5: 0.20803516 | L5: NaN | M5: 8900.4193 | N5: -5440.9023 | O5: 3459.517 | P5: 70.943216 | Q5: 359.15624 | R5: 805.91553 | S5: NaN | T5: -17216.95
A6: AUT | B6: 1994 | C6: 3923.1741 | D6: 3881.6031 | E6: 41.571 | F6: 2.4269782 | G6: -1.6189167 | H6: 0.80806153 | I6: 0.018176417 | J6: 0.087846174 | K6: 0.042287786 | L6: NaN | M6: 9521.458 | N6: -6351.2919 | O6: 3170.166 | P6: 71.309249 | Q6: 344.63583 | R6: 164.1444 | S6: NaN | T6: -13750.937
A7: AUT | B7: 1995 | C7: 3928.4501 | D7: 3886.8791 | E7: 41.571 | F7: 2.4250504 | G7: -1.4580083 | H7: 0.96704215 | I7: 0.044755632 | J7: 0.082828306 | K7: 0.20482557 | L7: NaN | M7: 9526.6896 | N7: -5727.7128 | O7: 3798.9768 | P7: 175.82027 | Q7: 325.38687 | R7: 796.13223 | S7: NaN | T7: -18686.493
A8: AUT | B8: 1996 | C8: 3933.7261 | D8: 3892.1551 | E8: 41.571 | F8: 2.2180108 | G8: -1.5754655 | H8: 0.64254534 | I8: 0.044817513 | J8: 0.077823899 | K8: 0.26602704 | L8: NaN | M8: 8725.0471 | N8: -6197.4497 | O8: 2527.5974 | P8: 176.29982 | Q8: 306.1379 | R8: 1035.4185 | S8: NaN | T8: -14833.33
A9: AUT | B9: 1997 | C9: 3939.0021 | D9: 3897.4311 | E9: 41.571 | F9: 2.807968 | G9: -1.5458976 | H9: 1.2620704 | I9: 0.044756547 | J9: 0.072832897 | K9: 0.17702399 | L9: NaN | M9: 11060.592 | N9: -6089.2939 | O9: 4971.298 | P9: 176.29613 | Q9: 286.88894 | R9: 689.9388 | S9: NaN | T9: -22456.214
